Workbook
Name CurrentMonth: #REF!
Name StartDate: 44227

Sheet Assumptions

Sheet Income Statement 
A1: Fiscal year is February-January. All values USD Millions. | B1: 2025 | C1: 2024 | D1: 2023 | E1: 2022 | F1: 2021 | G1: 5-year trend
A2: Sales/Revenue | B2: 130497 | C2: 60922 | D2: 26974 | E2: 26914 | F2: 16675
A3: Sales Growth | B3: 1.142 | C3: 1.2585 | D3: 0.0022 | E3: 0.614 | F3: -
A4: Cost of Goods Sold (COGS) incl. D&A | B4: 32639 | C4: 16621 | D4: 11618 | E4: 9439 | F4: 6279
A5: COGS excluding D&A | B5: 30775 | C5: 15113 | D5: 10074 | E5: 8265 | F5: 5181
A6: Depreciation & Amortization Expense | B6: 1864 | C6: 1508 | D6: 1544 | E6: 1174 | F6: 1098
A7: Depreciation | B7: 1271 | C7: 894 | D7: 845 | E7: 611 | F7: 486
A8: Amortization of Intangibles | B8: 593 | C8: 614 | D8: 699 | E8: 563 | F8: 612
A9: COGS Growth | B9: 0.9637 | C9: 0.4306 | D9: 0.2309 | E9: 0.5033 | F9: -
A10: Gross Income | B10: 97858 | C10: 44301 | D10: 15356 | E10: 17475 | F10: 10396
A11: Gross Income Growth | B11: 1.2089 | C11: 1.8849 | D11: -0.1213 | E11: 0.6809 | F11: -
A13: Gross Profit Margin | B13: 0.7499 | C13: - | D13: - | E13: - | F13: -
A14: SG&A Expense | B14: 16405 | C14: 11329 | D14: 9779 | E14: 7434 | F14: 5780
A15: Research & Development | B15: 12914 | C15: 8675 | D15: 7339 | E15: 5268 | F15: 3924
A16: Other SG&A | B16: 3491 | C16: 2654 | D16: 2440 | E16: 2166 | F16: 1856
A17: SGA Growth | B17: 0.4481 | C17: 0.1585 | D17: 0.3154 | E17: 0.2862 | F17: -
A18: EBIT | B18: 81453 | C18: 32972 | D18: 5577 | E18: 10041 | F18: 4616
A19: Unusual Expense | B19: -757 | C19: -174 | D19: 1414 | E19: -100 | F19: 84
A21: Non Operating Income/Expense | B21: 277 | C21: 63 | D21: 13 | E21: 7 | F21: 4
A22: Non-Operating Interest Income | B22: 1786 | C22: 866 | D22: 267 | E22: 29 | F22: 57
A23: Interest Expense | B23: 247 | C23: 257 | D23: 262 | E23: 236 | F23: 184
A24: Interest Expense Growth | B24: -0.0389 | C24: -0.0191 | D24: 0.1102 | E24: 0.2826 | F24: -
A26: Gross Interest Expense | B26: 247 | C26: 257 | D26: 262 | E26: 236 | F26: 184
A27: Pretax Income | B27: 84026 | C27: 33818 | D27: 4181 | E27: 9941 | F27: 4409
A28: Pretax Income Growth | B28: 1.4847 | C28: 7.0885 | D28: -0.5794 | E28: 1.2547 | F28: -
A30: Pretax Margin | B30: 0.6439 | C30: - | D30: - | E30: - | F30: -
A31: Income Tax | B31: 11146 | C31: 4058 | D31: -187 | E31: 189 | F31: 77
A33: Income Tax - Current Domestic | B33: 14924 | C33: 6045 | D33: 1749 | E33: 524 | F33: 198
A34: Income Tax - Current Foreign | B34: 699 | C34: 502 | D34: 228 | E34: 71 | F34: 161
A35: Income Tax - Deferred Domestic | B35: -4757 | C35: -2705 | D35: -2165 | E35: -420 | F35: -246
A37: Income Tax - Deferred Foreign | B37: 280 | C37: 216 | D37: 1 | E37: 14 | F37: -36
A39: Consolidated Net Income | B39: 72880 | C39: 29760 | D39: 4368 | E39: 9752 | F39: 4332
A40: Net Income | B40: 72880 | C40: 29760 | D40: 4368 | E40: 9752 | F40: 4332
A41: Net Income Growth | B41: 1.4489 | C41: 5.8132 | D41: -0.5521 | E41: 1.2512 | F41: -
A43: Net Margin | B43: 0.5585 | C43: - | D43: - | E43: - | F43: -
A44: Net Income After Extraordinaries | B44: 72880 | C44: 29760 | D44: 4368 | E44: 9752 | F44: 4332
A45: Net Income Available to Common | B45: 72880 | C45: 29760 | D45: 4368 | E45: 9752 | F45: 4332
A46: EPS (Basic) | B46: 2.94 | C46: 1.19 | D46: 0.17 | E46: 0.38 | F46: 0.17
A47: EPS (Basic) Growth | B47: 1.4622 | C47: 5.8502 | D47: -0.5472 | E47: 1.2301 | F47: -
A49: Basic Shares Outstanding | B49: 24555 | C49: 24690 | D49: 24870 | E49: 24960 | F49: 24680
...

Sheet Balance Sheet
A1: Assets
A2: Fiscal year is February-January. All values USD Millions. | B2: 2025 | C2: 2024 | D2: 2023 | E2: 2022 | F2: 2021 | G2: 5-year trend
A3: Cash & Short Term Investments | B3: 43210 | C3: 25984 | D3: 13296 | E3: 21208 | F3: 11561
A4: Cash Only | B4: 8589 | C4: 7280 | D4: 3389 | E4: 1990 | F4: 847
A5: Cash & Short Term Investments Growth | B5: 0.6629 | C5: 0.9543 | D5: -0.3731 | E5: 0.8344 | F5: -
A7: Cash & ST Investments / Total Assets | B7: 0.3872 | C7: 0.3953 | D7: 0.3229 | E7: 0.48 | F7: 0.4015
A8: Total Accounts Receivable | B8: 23065 | C8: 9999 | D8: 3827 | E8: 4650 | F8: 2429
A9: Accounts Receivables, Net | B9: 23065 | C9: 9999 | D9: 3827 | E9: 4650 | F9: 2429
A10: Accounts Receivables, Gross | B10: 23065 | C10: 9999 | D10: 3827 | E10: 4650 | F10: 2433
A11: Bad Debt/Doubtful Accounts | B11: - | C11: - | D11: - | E11: - | F11: -4
A13: Accounts Receivable Growth | B13: 1.3067 | C13: 1.6128 | D13: -0.177 | E13: 0.9144 | F13: -
A15: Accounts Receivable Turnover | B15: 5.66 | C15: 6.09 | D15: 7.05 | E15: 5.79 | F15: 6.86
A16: Inventories | B16: 10080 | C16: 5282 | D16: 5159 | E16: 2605 | F16: 1826
A17: Finished Goods | B17: 3273 | C17: 2058 | D17: 2263 | E17: 1122 | F17: 737
A18: Work in Progress | B18: 3399 | C18: 1505 | D18: 466 | E18: 692 | F18: 457
A19: Raw Materials | B19: 3408 | C19: 1719 | D19: 2430 | E19: 791 | F19: 632
A20: Other Current Assets | B20: 3771 | C20: 3080 | D20: 791 | E20: 366 | F20: 239
A21: Prepaid Expenses | B21: 3300 | C21: - | D21: - | E21: - | F21: -
A22: Miscellaneous Current Assets | B22: 471 | C22: 3080 | D22: 791 | E22: 366 | F22: 239
A23: Total Current Assets | B23: 80126 | C23: 44345 | D23: 23073 | E23: 28829 | F23: 16055
A24: Net Property, Plant & Equipment | B24: 8076 | C24: 5260 | D24: 4845 | E24: 3607 | F24: 2856
A25: Property, Plant & Equipment - Gross | B25: 12477 | C25: 8769 | D25: 7539 | E25: 5510 | F25: 4264
A26: Buildings | B26: - | C26: - | D26: - | E26: - | F26: 341
A27: Land & Improvements | B27: 511 | C27: 218 | D27: 218 | E27: 218 | F27: 218
A28: Machinery & Equipment | B28: - | C28: - | D28: - | E28: - | F28: 782
A29: Construction in Progress | B29: 529 | C29: 189 | D29: 382 | E29: 737 | F29: 558
A30: Computer Software and Equipment | B30: 7568 | C30: 5200 | D30: 4303 | E30: 2852 | F30: 1187
A31: Other Property, Plant & Equipment | B31: 2076 | C31: 1816 | D31: 1598 | E31: 874 | F31: 471
A32: Accumulated Depreciation | B32: 4401 | C32: 3509 | D32: 2694 | E32: 1903 | F32: 1408
A33: Total Investments and Advances | B33: 3387 | C33: 1546 | D33: 299 | E33: 266 | F33: -
A34: Other Long-Term Investments | B34: 3387 | C34: 1546 | D34: 299 | E34: 266 | F34: -
A35: Intangible Assets | B35: 5995 | C35: 5542 | D35: 6048 | E35: 6688 | F35: 6930
A36: Net Goodwill | B36: 5188 | C36: 4430 | D36: 4372 | E36: 4349 | F36: 4193
A37: Net Other Intangibles | B37: 807 | C37: 1112 | D37: 1676 | E37: 2339 | F37: 2737
A38: Other Assets | B38: 3038 | C38: 2954 | D38: 3521 | E38: 3575 | F38: 2144
A39: Deferred Charges | B39: 2087 | C39: 2822 | D39: 3376 | E39: 2156 | F39: -
A40: Tangible Other Assets | B40: 951 | C40: 132 | D40: 145 | E40: 1419 | F40: 2144
A41: Total Assets | B41: 111601 | C41: 65728 | D41: 41182 | E41: 44187 | F41: 28791
A42: Assets - Total - Growth | B42: 0.6979 | C42: 0.596 | D42: -0.068 | E42: 0.5348 | F42: -
A44: Asset Turnover | B44: 1.47 | C44: - | D44: - | E44: - | F44: -
...

Sheet Cash Flow 
A1: Operating Activities
A2: Fiscal year is February-January. All values USD Millions. | B2: 2025 | C2: 2024 | D2: 2023 | E2: 2022 | F2: 2021 | G2: 5-year trend
A3: Net Income before Extraordinaries | B3: 72880 | C3: 29760 | D3: 4368 | E3: 9752 | F3: 4332
A4: Net Income Growth | B4: 1.4489 | C4: 5.8132 | D4: -0.5521 | E4: 1.2512 | F4: -
A6: Depreciation, Depletion & Amortization | B6: 1864 | C6: 1508 | D6: 1544 | E6: 1174 | F6: 1098
A7: Depreciation and Depletion | B7: 1271 | C7: 894 | D7: 845 | E7: 611 | F7: 486
A8: Amortization of Intangible Assets | B8: 593 | C8: 614 | D8: 699 | E8: 563 | F8: 612
A9: Deferred Taxes & Investment Tax Credit | B9: -4477 | C9: -2489 | D9: -2164 | E9: -406 | F9: -282
A11: Deferred Taxes | B11: -4477 | C11: -2489 | D11: -2164 | E11: -406 | F11: -282
A13: Other Funds | B13: 3205 | C13: 3033 | D13: 4100 | E13: 1951 | F13: 1377
A14: Funds from Operations | B14: 73472 | C14: 31812 | D14: 7848 | E14: 12471 | F14: 6525
A15: Changes in Working Capital | B15: -9383 | C15: -3722 | D15: -2207 | E15: -3363 | F15: -703
A17: Receivables | B17: -13063 | C17: -6172 | D17: 822 | E17: -2215 | F17: -550
A19: Inventories | B19: -4781 | C19: -98 | D19: -2554 | E19: -774 | F19: -524
A21: Accounts Payable | B21: 3357 | C21: 1531 | D21: -551 | E21: 568 | F21: 363
A23: Other Accruals | B23: 4278 | C23: 2025 | D23: 1341 | E23: 581 | F23: 239
... A26: Net Operating Cash Flow | B26: 64089 | C26: 28090 | D26: 5641 | E26: 9108 | F26: 5822
A27: Net Operating Cash Flow Growth | B27: 1.2816 | C27: 3.9796 | D27: -0.3807 | E27: 0.5644 | F27: -
A29: Net Operating Cash Flow / Sales | B29: 0.4911 | C29: 0.4611 | D29: 0.2091 | E29: 0.3384 | F29: 0.3491
A30: Investing Activities
A31: All values USD Millions. | B31: 2025 | C31: 2024 | D31: 2023 | E31: 2022 | F31: 2021 | G31: 5-year trend
A32: Capital Expenditures | B32: -3236 | C32: -1069 | D32: -1833 | E32: -976 | F32: -1128
A34: Capital Expenditures (Fixed Assets) | B34: -3236 | C34: -1069 | D34: -1833 | E34: -976 | F34: -1128
A36: Capital Expenditures Growth | B36: -2.0271 | C36: 0.4168 | D36: -0.8781 | E36: 0.1348 | F36: -
A38: Capital Expenditures / Sales | B38: -0.0248 | C38: -0.0175 | D38: -0.068 | E38: -0.0363 | F38: -0.0676
A40: Net Assets from Acquisitions | B40: -1007 | C40: -83 | D40: -49 | E40: -263 | F40: -8524
A42: Purchase/Sale of Investments | B42: -16200 | C42: -8429 | D42: 9334 | E42: -8567 | F42: -9989
A44: Purchase of Investments | B44: -28061 | C44: -18211 | D44: -11897 | E44: -24787 | F44: -19308
A46: Sale/Maturity of Investments | B46: 11861 | C46: 9782 | D46: 21231 | E46: 16220 | F46: 9319
A47: Other Uses | B47: - | C47: -985 | D47: -77 | E47: -24 | F47: -34
A49: Other Sources | B49: 22 | C49: - | D49: - | E49: - | F49: -
A50: Net Investing Cash Flow | B50: -20421 | C50: -10566 | D50: 7375 | E50: -9830 | F50: -19675
A52: Net Investing Cash Flow Growth | B52: -0.9327 | C52: -2.4327 | D52: 1.7503 | E52: 0.5004 | F52: -
A54: Net Investing Cash Flow / Sales | B54: -0.1565 | C54: -0.1734 | D54: 0.2734 | E54: -0.3652 | F54: -1.1799
A55: Financing Activities
A56: All values USD Millions. | B56: 2025 | C56: 2024 | D56: 2023 | E56: 2022 | F56: 2021 | G56: 5-year trend
A57: Cash Dividends Paid - Total | B57: -834 | C57: -395 | D57: -398 | E57: -399 | F57: -395
A59: Common Dividends | B59: -834 | C59: -395 | D59: -398 | E59: -399 | F59: -395
A61: Change in Capital Stock | B61: -33216 | C61: -9130 | D61: -9684 | E61: 281 | F61: 194
A63: Repurchase of Common & Preferred Stk. | B63: -33706 | C63: -9533 | D63: -10039 | E63: - | F63: -
...

Sheet Free Cash Flows
A1: Unlevered FreeCash Flow
A2: Fiscal year | D2: 2021 | E2: 2022 | F2: 2023 | G2: 2024 | H2: 2025 | I2: 2026 | J2: 2027 | K2: 2028 | L2: 2029 | M2: 2030
A3: Revenue | D3: 16675 | E3: 26914 | F3: 26974 | G3: 60922 | H3: 130497 | I3: =H3*(1+I24) -> 165209.2 | J3: =I3*(1+J24) -> 209154.85 | K3: =J3*(1+K24) -> 264790.04 | L3: =K3*(1+L24) -> 335224.19 | M3: =L3*(1+M24) -> 424393.82
A4: COGS | D4: 6279 | E4: 9439 | F4: 11618 | G4: 16621 | H4: 32639 | I4: =H4*I25 -> 10972.643 | J4: =I4*J25 -> 3688.8044 | K4: =J4*K25 -> 1240.1094 | L4: =K4*L25 -> 416.90241 | M4: =L4*M25 -> 140.15506
A5: Gross Profit | D5: =D3-D4 -> 10396 | E5: =E3-E4 -> 17475 | F5: =F3-F4 -> 15356 | G5: =G3-G4 -> 44301 | H5: =H3-H4 -> 97858 | I5: =I3-I4 -> 154236.56 | J5: =J3-J4 -> 205466.05 | K5: =K3-K4 -> 263549.93 | ... M5: =M3-M4 -> 424253.67
A6: Operating Exp
A7: SG&A Exp | D7: 5836 | E7: 7434 | F7: 9779 | G7: 11329 | H7: 16405 | I7: =I5*I25 -> 51851.547 | J7: =J5*J25 -> 69073.976 | K7: =K5*K25 -> 88600.729 | L7: =L5*L25 -> 112556.17 | M7: =M5*M25 -> 142626.43
A8: Total Operating exp | D8: =D7 -> 5836 | E8: =E7 -> 7434 | F8: =F7 -> 9779 | G8: =G7 -> 11329 | H8: =H7 -> 16405 | I8: =I7 -> 51851.547 | J8: =J7 -> 69073.976 | K8: =K7 -> 88600.729 | ... M8: =M7 -> 142626.43
A9: EBITDA | D9: =D11+D10 -> 5714 | E9: =E11+E10 -> 11215 | F9: =F11+F10 -> 7121 | G9: =G11+G10 -> 34480 | H9: =H11+H10 -> 83317 | I9: =I5-I8 -> 102385.01 | J9: =J5-J8 -> 136392.07 | K9: =K5-K8 -> 174949.2 | L9: =L5-L8 -> 222251.12 | M9: =M5-M8 -> 281627.24
A10: Depreciation&Amortization | D10: 1098 | E10: 1174 | F10: 1544 | G10: 1508 | H10: 1864 | I10: 2826.6 | J10: 3391.92 | K10: 4070.304 | L10: 4884.3648 | M10: 5861.2378
A11: Operatinhg Profit(EBIT) | D11: 4616 | E11: 10041 | F11: 5577 | G11: 32972 | H11: 81453 | I11: =I9-I10 -> 99558.412 | J11: =J9-J10 -> 133000.15 | K11: =K9-K10 -> 170878.9 | L11: =L9-L10 -> 217366.76 | M11: =M9-M10 -> 275766.01
A12: Operating Taxes | D12: 77 | E12: 189 | F12: -187 | G12: 4058 | H12: 11146 | I12: =I11*I27 -> 16427.138 | J12: =J11*J27 -> 21945.025 | K12: =K11*K27 -> 28195.018 | L12: =L11*L27 -> 35865.515 | M12: =M11*M27 -> 45501.391
A13: NOPAT | D13: =D11-D12 -> 4539 | E13: =E11-E12 -> 9852 | F13: =F11-F12 -> 5764 | G13: =G11-G12 -> 28914 | H13: =H11-H12 -> 70307 | I13: =I11-I12 -> 83131.274 | J13: =J11-J12 -> 111055.13 | K13: =K11-K12 -> 142683.88 | ... M13: =M11-M12 -> 230264.62
A14: (+) D&A | D14: 1098 | E14: 1174 | F14: 1544 | G14: 1508 | H14: 1864 | I14: =I10 -> 2826.6 | J14: =J10 -> 3391.92 | K14: =K10 -> 4070.304 | L14: =L10 -> 4884.3648 | M14: =M10 -> 5861.2378
A15: (-)Capex | D15: 1130 | E15: 976 | F15: 1830 | G15: 1070 | H15: 3240 | I15: 4442 | J15: 5530.16 | K15: 6396.192 | L15: 7675.4304 | M15: 9210.5165
A16: (-)change in nwc | D16: -703 | E16: -3363 | F16: -2207 | G16: -3722 | H16: -9383 | I16: =I17-H17 -> -2569.1919 | J16: =J17-I17 -> 16286.939 | K16: =K17-J17 -> 20388.588 | L16: =L17-K17 -> 27096.98 | M16: =M17-L17 -> 32734.505
A17: NWC | D17: =D18-D19 -> 12130 | E17: =E18-E19 -> 24494 | F17: =F18-F19 -> 16510 | G17: =G18-G19 -> 33714 | H17: =H18-H19 -> 62079 | I17: =I18-I19 -> 59509.808 | J17: =J18-J19 -> 75796.747 | K17: =K18-K19 -> 96185.335 | ... M17: =M18-M19 -> 156016.82
A18: Current operating assents | D18: 16055 | E18: 28829 | F18: 23073 | G18: 44345 | H18: 80126 | I18: ='Working Capital '!H6 -> 94204.918 | J18: ='Working Capital '!I6 -> 119263.43 | K18: ='Working Capital '!J6 -> 150987.5 | L18: ='Working Capital '!K6 -> 191150.17 | M18: ='Working Capital '!L6 -> 241996.12
A19: current operating liab | D19: 3925 | E19: 4335 | F19: 6563 | G19: 10631 | H19: 18047 | I19: ='Working Capital '!H10 -> 34695.11 | J19: ='Working Capital '!I10 -> 43466.679 | K19: ='Working Capital '!J10 -> 54802.163 | L19: ='Working Capital '!K10 -> 67867.858 | M19: ='Working Capital '!L10 -> 85979.299
A20: free cash flow | D20: =D13+D14-D15-D16 -> 5210 | E20: =E13+E14-E15-E16 -> 13413 | F20: =F13+F14-F15-F16 -> 7685 | G20: =G13+G14-G15-G16 -> 33074 | H20: =H13+H14-H15-H16 -> 78314 | I20: =I13+I14-I15-I16 -> 84085.066 | J20: =J13+J14-J15-J16 -> 92629.946 | K20: =K13+K14-K15-K16 -> 119969.4 | ... M20: =M13+M14-M15-M16 -> 194180.83
A22: Assumptions
A23: fiscal year | D23: 2021 | E23: 2022 | F23: 2023 | G23: 2024 | H23: 2025 | I23: 2026 | J23: 2027 | K23: 2028 | L23: 2029 | M23: 2030 | O23: https://finance.yahoo.com/news/prediction-nvidia-soar-over-next-162100138.html
A24: revenue growth | E24: =E3/D3-E341 -> 1.614033 | F24: =F3/E3-1 -> 0.002229323 | G24: =G3/F3-1 -> 1.2585453 | H24: =H3/G3-1 -> 1.1420341 | I24: 0.266 | J24: 0.266 | K24: 0.266 | L24: 0.266 | M24: 0.266
A25: COGS %of revenue | D25: =D4/D3 -> 0.37655172 | E25: =E4/E3 -> 0.35070967 | F25: =F4/F3 -> 0.43071106 | G25: =G4/G3 -> 0.27282427 | H25: =H4/H3 -> 0.25011303 | I25: =AVERAGE(D25:H25) -> 0.33618195 | J25: =I25 -> 0.33618195 | K25: =J25 -> 0.33618195 | L25: =K25 -> 0.33618195 | M25: =L25 -> 0.33618195
A26: SG&A % of Revenue | D26: =D7/D3 -> 0.34998501 | E26: =E7/E3 -> 0.27621312 | F26: =F7/F3 -> 0.36253429 | G26: =G7/G3 -> 0.1859591 | H26: =H7/H3 -> 0.1257117 | I26: =AVERAGE(D26:H26) -> 0.26008064 | J26: =I26 -> 0.26008064 | K26: =J26 -> 0.26008064 | L26: =K26 -> 0.26008064 | M26: =L26 -> 0.26008064
A27: tax %of EBIT | D27: =D12/D11 -> 0.016681109 | E27: =E12/E11 -> 0.018822826 | F27: =F12/F11 -> -0.033530572 | G27: =G12/G11 -> 0.12307412 | H27: =H12/H11 -> 0.13683965 | I27: 0.165 | J27: =I27 -> 0.165 | K27: =J27 -> 0.165 | L27: =K27 -> 0.165 | M27: =L27 -> 0.165
A30: =E3-D3 -> 10239
A31: =A30/D3 -> 0.61403298

Sheet Fixed Assets 
A1: Fixed Asset Schedule
A2: fiscal year | B2: 2021 | C2: 2022 | D2: 2023 | E2: 2024 | F2: 2025 | G2: 2026 | H2: 2027 | I2: 2028 | J2: 2029 | K2: 2030
A3: beg PP&E | B3: 1674 | C3: 2856 | D3: 3607 | E3: 4845 | F3: 5260 | G3: =F6 -> 8076 | H3: =G6 -> 9691.2 | I3: =H6 -> 11629.44 | J3: =I6 -> 13955.328 | K3: =J6 -> 16746.394
A4: D&A | B4: 1098 | C4: 1174 | D4: 1544 | E4: 1508 | F4: 1864 | G4: =G3*G10 -> 2826.6 | H4: =H3*H10 -> 3391.92 | I4: =I3*I10 -> 4070.304 | J4: =J3*J10 -> 4884.3648 | K4: =K3*K10 -> 5861.2378
A5: Cap Ex | B5: 1130 | C5: 976 | D5: 1830 | E5: 1070 | F5: 3240 | G5: =G3*G11 -> 4441.8 | H5: =H3*H11 -> 5330.16 | I5: =I3*I11 -> 6396.192 | J5: =J3*J11 -> 7675.4304 | K5: =K3*K11 -> 9210.5165
A6: Ending PP&E | B6: 2856 | C6: 3607 | D6: 4845 | E6: 5260 | F6: 8076 | G6: =G3-G4+G5 -> 9691.2 | H6: =H3-H4+H5 -> 11629.44 | I6: =I3-I4+I5 -> 13955.328 | J6: =J3-J4+J5 -> 16746.394 | K6: =K3-K4+K5 -> 20095.672
A8: Assumptions
A9: fiscal year | B9: 2021 | C9: 2022 | D9: 2023 | E9: 2024 | F9: 2025 | G9: 2026 | H9: 2027 | I9: 2028 | J9: 2029 | K9: 2030
A10: D&A as % of beg PPE | B10: =B4/B3 -> 0.65591398 | C10: =C4/C3 -> 0.41106443 | D10: =D4/D3 -> 0.42805656 | E10: =E4/E3 -> 0.31124871 | F10: =F4/F3 -> 0.35437262 | G10: 0.35 | H10: 0.35 | I10: 0.35 | J10: 0.35 | K10: 0.35
A11: CapEx as a % of PP&E | B11: =B5/B3 -> 0.67502987 | C11: =C5/C3 -> 0.34173669 | D11: =D5/D3 -> 0.50734683 | E11: =E5/E3 -> 0.22084623 | F11: =F5/F3 -> 0.61596958 | G11: 0.55 | H11: 0.55 | I11: 0.55 | J11: 0.55 | K11: 0.55

Sheet Working Capital 
A1: Net Working Capital
A2: Fiscal Year | C2: 2021 | D2: 2022 | E2: 2023 | F2: 2024 | G2: 2025 | H2: 2026 | I2: 2027 | J2: 2028 | K2: 2029 | L2: 2030
A3: Accounts Recievable | C3: 2429 | D3: 4650 | E3: 3827 | F3: 9999 | G3: 23065 | H3: =H18*H15/360 -> 26472.869 | I3: =I18*I15/360 -> 33514.652 | J3: =J18*J15/360 -> 42429.549 | K3: =K18*K15/360 -> 53715.81 | L3: =L18*L15/360 -> 68004.215
A4: Merchandise Inventory | C4: 1826 | D4: 2605 | E4: 5159 | F4: 5282 | G4: 10080 | H4: =H19*H16/360 -> 18189.124 | I4: =I19*I16/360 -> 23027.432 | J4: =J19*J16/360 -> 29152.728 | K4: =K19*K16/360 -> 36907.354 | L4: =L19*L16/360 -> 46724.71
A5: Other Current Assets | C5: 239 | D5: 366 | E5: 791 | F5: 3080 | G5: 3771 | H5: =H22*H15 -> 49542.925 | I5: =I22*I15 -> 62721.343 | J5: =J22*J15 -> 79405.22 | K5: =K22*K15 -> 100527.01 | L5: =L22*L15 -> 127267.19
A6: Current Assets | C6: =SUM(C3:C5) -> 4494 | D6: =SUM(D3:D5) -> 7621 | E6: =SUM(E3:E5) -> 9777 | F6: =SUM(F3:F5) -> 18361 | G6: =SUM(G3:G5) -> 36916 | H6: =SUM(H3:H5) -> 94204.918 | I6: =SUM(I3:I5) -> 119263.43 | J6: =SUM(J3:J5) -> 150987.5 | ... L6: =SUM(L3:L5) -> 241996.12
A8: Accounts payable | C8: 1201 | D8: 1783 | E8: 1193 | F8: 2699 | G8: 6310 | H8: =H20*H16/360 -> 9314.8617 | I8: =I20*I16/360 -> 11792.615 | J8: =J20*J16/360 -> 14929.451 | K8: =K20*K16/360 -> 18900.684 | L8: =L20*L16/360 -> 23928.266
A9: Other Current Liabilities | C9: 1543 | D9: 2408 | E9: 3477 | F9: 6158 | G9: 10568 | H9: =H23*H15 -> 25380.249 | I9: =I23*I15 -> 31674.064 | J9: =J23*J15 -> 39872.712 | K9: =K23*K15 -> 48967.173 | L9: =L23*L15 -> 62051.032
A10: Current Liab | C10: =SUM(C8:C9) -> 2744 | D10: =SUM(D8:D9) -> 4191 | E10: =SUM(E8:E9) -> 4670 | F10: =SUM(F8:F9) -> 8857 | G10: =SUM(G8:G9) -> 16878 | H10: =SUM(H8:H9) -> 34695.11 | I10: =SUM(I8:I9) -> 43466.679 | J10: =SUM(J8:J9) -> 54802.163 | ... L10: =SUM(L8:L9) -> 85979.299
A13: assumptions
A14: Fiscal year | C14: 2021 | D14: 2022 | E14: 2023 | F14: 2024 | G14: 2025 | H14: 2026 | I14: 2027 | J14: 2028 | K14: 2029 | L14: 2030
A15: Revenue | C15: 16675 | D15: 26914 | E15: 26974 | F15: 60922 | G15: 130497 | H15: =G15+(G15*'Free Cash Flows'!I24) -> 165209.2 | I15: =H15+(H15*'Free Cash Flows'!J24) -> 209154.85 | J15: =I15+(I15*'Free Cash Flows'!K24) -> 264790.04 | K15: =J15+(J15*'Free Cash Flows'!L24) -> 335224.19 | L15: =K15+(K15*'Free Cash Flows'!M24) -> 424393.82
A16: COGS | C16: 6279 | D16: 9439 | E16: 11618 | F16: 16621 | G16: 32639 | H16: =H15*'Free Cash Flows'!I25 -> 55540.351 | I16: =I15*'Free Cash Flows'!J25 -> 70314.085 | J16: =J15*'Free Cash Flows'!K25 -> 89017.632 | K16: =K15*'Free Cash Flows'!L25 -> 112696.32 | L16: =L15*'Free Cash Flows'!M25 -> 142673.54
A18: Days Sales Oustanding (DSO) | C18: =C3/C15*360 -> 52.44018 | D18: =D3/D15*360 -> 62.198113 | E18: =E3/E15*360 -> 51.075851 | F18: =F3/F15*360 -> 59.086044 | G18: =G3/G15*360 -> 63.629049 | H18: =AVERAGE(C18:G$18) -> 57.685847 | I18: =AVERAGE(C18:H$18) -> 57.685847 | J18: =AVERAGE(C18:I$18) -> 57.685847 | K18: =AVERAGE(C18:J$18) -> 57.685847 | L18: =AVERAGE(C18:K$18) -> 57.685847
A19: Days Inventory Outstanding (DIO) | C19: =(C4/C16)*360 -> 104.69183 | D19: =(D4/D16)*360 -> 99.353745 | E19: =(E4/E16)*360 -> 159.85884 | F19: =(F4/F16)*360 -> 114.40467 | G19: =(G4/G16)*360 -> 111.17988 | H19: =AVERAGE(C19:G19) -> 117.89779 | I19: =AVERAGE(C19:H19) -> 117.89779 | J19: =AVERAGE(C19:I19) -> 117.89779 | K19: =AVERAGE(C19:J19) -> 117.89779 | L19: =AVERAGE(C19:K19) -> 117.89779
A20: Days Payable Outstanding (DPO) | C20: =C8/C16*360 -> 68.858098 | D20: =D8/D16*360 -> 68.002966 | E20: =E8/E16*360 -> 36.966776 | F20: =F8/F16*360 -> 58.458576 | G20: =G8/G16*360 -> 69.597721 | H20: =AVERAGE(C20:G20) -> 60.376828 | I20: =AVERAGE(C20:H20) -> 60.376828 | J20: =AVERAGE(C20:I20) -> 60.376828 | K20: =AVERAGE(C20:J20) -> 60.376828 | L20: =AVERAGE(C20:K20) -> 60.376828
A22: Other current assets as % of rev | C22: =C6/C$15 -> 0.26950525 | D22: =D6/D$15 -> 0.28316118 | E22: =E6/E$15 -> 0.36246015 | F22: =F6/F$15 -> 0.30138538 | G22: =G6/G$15 -> 0.28288773 | H22: =AVERAGE(C22:G22) -> 0.29987994 | I22: =H22 -> 0.29987994 | J22: =I22 -> 0.29987994 | K22: =J22 -> 0.29987994 | L22: =K22 -> 0.29987994
A23: other current liab as % of rev | C23: =C10/C15 -> 0.16455772 | D23: =D10/D15 -> 0.15571821 | E23: =E10/E15 -> 0.17312968 | F23: =F10/F15 -> 0.14538262 | G23: =G10/G15 -> 0.12933631 | H23: =AVERAGE(C23:G23) -> 0.15362491 | I23: =AVERAGE(D23:H23) -> 0.15143835 | J23: =AVERAGE(E23:I23) -> 0.15058237 | K23: =AVERAGE(F23:J23) -> 0.14607291 | L23: =AVERAGE(G23:K23) -> 0.14621097

Sheet DCF
A1: Unlevered Free Cash Flow (mm)
A2: Fiscal Year | D2: 2021 | E2: 2022 | F2: 2023 | G2: 2024 | H2: 2025 | I2: 2026 | J2: 2027 | K2: 2028 | L2: 2029 | M2: 2030 | O2: PV of FCF | P2: =SUM(I7:M7) -> 585228.95
A3: Unlevered Free Cash Flow (mm) | D3: ='Free Cash Flows'!D20 -> 5210 | E3: ='Free Cash Flows'!E20 -> 13413 | F3: ='Free Cash Flows'!F20 -> 7685 | G3: ='Free Cash Flows'!G20 -> 33074 | H3: ='Free Cash Flows'!H20 -> 78314 | I3: ='Free Cash Flows'!I20 -> 84085.066 | J3: ='Free Cash Flows'!J20 -> 92629.946 | K3: ='Free Cash Flows'!K20 -> 119969.4 | ... M3: ='Free Cash Flows'!M20 -> 194180.83 | O3: PV of Terminal Value | P3: =D18/(1+D16)^5 -> 2190116
A6: Projecton Year | I6: 1 | J6: 2 | K6: 3 | L6: 4 | M6: 5
A7: Present Value of Free Cash Flow | I7: =I3/(1+$D$16)^1 -> 76592.477 | J7: =J3/(1+$D$16)^1 -> 84375.946 | K7: =K3/(1+$D$16)^1 -> 109279.26 | L7: =L3/(1+$D$16)^1 -> 138103.36 | M7: =M3/(1+$D$16)^1 -> 176877.91
A14: Implied Share Price Calculator
A15: Sum of PV of FCF | D15: =SUM(I7:M7) -> 585228.95
A16: WACC | D16: =C46 -> 0.097824088
A17: Growth Rate | D17: 0.04
A18: Terminal Value | D18: =M3*(1+D17)/(D16-D17) -> 3492455.7
A19: PV of Terminal Value | D19: =D18/(1+D16)^5 -> 2190116
A20: Enterprise Value | D20: =D19+D15 -> 2775345 | H20: \
A21: (+) Cash | D21: 43210
A22: (-) debt | D22: ='[1]Balance Sheet'!$I$63 -> 9780
A23: (-) minority interest
A24: Equity Value | D24: =D20+D21-D22 -> 2808775
A25: Diluted Shares Outstanding | D25: 24477
A26: Implied Share Price | D26: =D24/D25 -> 114.7516
A31: Weighted Average Cost of Capital (WACC)
A32: Equity (mm) | C32: =4217052 -> 4217052
A33: Debt(mm) | C33: ='[1]Balance Sheet'!$I$63 -> 9780
A34: Cost of Debt | C34: =247/C33 -> 0.025255624
A35: Tax Rate | C35: 0.13
A36: D/(D+E) | C36: =C33/SUM(C32:C33) -> 0.0023137896
A37: Afert Tax Cost of Debt | C37: =C34*(1-C35) -> 0.021972393
A39: Risk Free Rate (10-yr Treasury Yield) | C39: 0.03
A40: Expected Market Return | C40: 0.1
A41: Market Risk Premium | C41: =C40-C39 -> 0.07
A42: Levered Beta | C42: 1.7
A43: E/(D+E) | C43: =C32/SUM(C32:C33) -> 0.99768621
A44: Cost Of Equity | C44: =C39+C42*(C41-C39) -> 0.098
A46: WAAC | C46: =C37*C36+C44*C43 -> 0.097824088

Sheet Sources 
A1: Sources
